int test() {
    throw("have exception")
    return 1
}


# 不处理异常，此时如果出现异常则继续自动向上 throw, 类似 if err != ni return err
var i = test()

# 处理异常
var i,error = test().catch()
// handle error
if (error) {
  i = default_value
}